Got a 500 code response to https://quantumexperience.ng.bluemix.net/api/Jobs?access_token=5OCuBPo3iUNHaFuEm8je7vhqkNgYfeRNz5GMi8En8JgT6JL3nAmKnToryVfR9Vh1: 500 Error: Failed to establish a backside connection
Traceback (most recent call last):
  File "/home/sesmart/.conda/envs/scott/lib/python3.5/site-packages/urllib3/connection.py", line 141, in _new_conn
    (self.host, self.port), self.timeout, **extra_kw)
  File "/home/sesmart/.conda/envs/scott/lib/python3.5/site-packages/urllib3/util/connection.py", line 83, in create_connection
    raise err
  File "/home/sesmart/.conda/envs/scott/lib/python3.5/site-packages/urllib3/util/connection.py", line 73, in create_connection
    sock.connect(sa)
TimeoutError: [Errno 110] Connection timed out

During handling of the above exception, another exception occurred:

Traceback (most recent call last):
  File "/home/sesmart/.conda/envs/scott/lib/python3.5/site-packages/urllib3/connectionpool.py", line 601, in urlopen
    chunked=chunked)
  File "/home/sesmart/.conda/envs/scott/lib/python3.5/site-packages/urllib3/connectionpool.py", line 346, in _make_request
    self._validate_conn(conn)
  File "/home/sesmart/.conda/envs/scott/lib/python3.5/site-packages/urllib3/connectionpool.py", line 850, in _validate_conn
    conn.connect()
  File "/home/sesmart/.conda/envs/scott/lib/python3.5/site-packages/urllib3/connection.py", line 284, in connect
    conn = self._new_conn()
  File "/home/sesmart/.conda/envs/scott/lib/python3.5/site-packages/urllib3/connection.py", line 150, in _new_conn
    self, "Failed to establish a new connection: %s" % e)
urllib3.exceptions.NewConnectionError: <urllib3.connection.VerifiedHTTPSConnection object at 0x2b1ba0030dd8>: Failed to establish a new connection: [Errno 110] Connection timed out

During handling of the above exception, another exception occurred:

Traceback (most recent call last):
  File "/home/sesmart/.conda/envs/scott/lib/python3.5/site-packages/requests/adapters.py", line 440, in send
    timeout=timeout
  File "/home/sesmart/.conda/envs/scott/lib/python3.5/site-packages/urllib3/connectionpool.py", line 639, in urlopen
    _stacktrace=sys.exc_info()[2])
  File "/home/sesmart/.conda/envs/scott/lib/python3.5/site-packages/urllib3/util/retry.py", line 388, in increment
    raise MaxRetryError(_pool, url, error or ResponseError(cause))
urllib3.exceptions.MaxRetryError: HTTPSConnectionPool(host='quantumexperience.ng.bluemix.net', port=443): Max retries exceeded with url: /api/Backends?access_token=5OCuBPo3iUNHaFuEm8je7vhqkNgYfeRNz5GMi8En8JgT6JL3nAmKnToryVfR9Vh1 (Caused by NewConnectionError('<urllib3.connection.VerifiedHTTPSConnection object at 0x2b1ba0030dd8>: Failed to establish a new connection: [Errno 110] Connection timed out',))

During handling of the above exception, another exception occurred:

Traceback (most recent call last):
  File "/home/sesmart/.conda/envs/scott/lib/python3.5/site-packages/qiskit/backends/ibmq/ibmqbackend.py", line 150, in status
    status = self._api.backend_status(backend_name)
  File "/home/sesmart/.conda/envs/scott/lib/python3.5/site-packages/IBMQuantumExperience/IBMQuantumExperience.py", line 874, in backend_status
    backend_type = self._check_backend(backend, 'status')
  File "/home/sesmart/.conda/envs/scott/lib/python3.5/site-packages/IBMQuantumExperience/IBMQuantumExperience.py", line 498, in _check_backend
    backends = self.available_backends()
  File "/home/sesmart/.conda/envs/scott/lib/python3.5/site-packages/IBMQuantumExperience/IBMQuantumExperience.py", line 965, in available_backends
    ret = self.req.get(url)
  File "/home/sesmart/.conda/envs/scott/lib/python3.5/site-packages/IBMQuantumExperience/IBMQuantumExperience.py", line 362, in get
    **self.extra_args)
  File "/home/sesmart/.conda/envs/scott/lib/python3.5/site-packages/requests/api.py", line 72, in get
    return request('get', url, params=params, **kwargs)
  File "/home/sesmart/.conda/envs/scott/lib/python3.5/site-packages/requests/api.py", line 58, in request
    return session.request(method=method, url=url, **kwargs)
  File "/home/sesmart/.conda/envs/scott/lib/python3.5/site-packages/requests/sessions.py", line 508, in request
    resp = self.send(prep, **send_kwargs)
  File "/home/sesmart/.conda/envs/scott/lib/python3.5/site-packages/requests/sessions.py", line 618, in send
    r = adapter.send(request, **kwargs)
  File "/home/sesmart/.conda/envs/scott/lib/python3.5/site-packages/requests/adapters.py", line 508, in send
    raise ConnectionError(e, request=request)
requests.exceptions.ConnectionError: HTTPSConnectionPool(host='quantumexperience.ng.bluemix.net', port=443): Max retries exceeded with url: /api/Backends?access_token=5OCuBPo3iUNHaFuEm8je7vhqkNgYfeRNz5GMi8En8JgT6JL3nAmKnToryVfR9Vh1 (Caused by NewConnectionError('<urllib3.connection.VerifiedHTTPSConnection object at 0x2b1ba0030dd8>: Failed to establish a new connection: [Errno 110] Connection timed out',))

During handling of the above exception, another exception occurred:

Traceback (most recent call last):
  File "/home/sesmart/3_vqa/hqca/tools/QuantumFramework.py", line 151, in wait_for_machine
    use,pending = check(qo)
  File "/home/sesmart/3_vqa/hqca/tools/IBM_check.py", line 27, in check
    test = backend_object.status
  File "/home/sesmart/.conda/envs/scott/lib/python3.5/site-packages/qiskit/backends/ibmq/ibmqbackend.py", line 171, in status
    "Couldn't get backend status: {0}".format(ex))
LookupError: Couldn't get backend status: HTTPSConnectionPool(host='quantumexperience.ng.bluemix.net', port=443): Max retries exceeded with url: /api/Backends?access_token=5OCuBPo3iUNHaFuEm8je7vhqkNgYfeRNz5GMi8En8JgT6JL3nAmKnToryVfR9Vh1 (Caused by NewConnectionError('<urllib3.connection.VerifiedHTTPSConnection object at 0x2b1ba0030dd8>: Failed to establish a new connection: [Errno 110] Connection timed out',))

During handling of the above exception, another exception occurred:

Traceback (most recent call last):
  File "/home/sesmart/3_vqa/hqca/tools/QuantumFramework.py", line 158, in wait_for_machine
    register(Qconfig.APItoken)
NameError: name 'register' is not defined

During handling of the above exception, another exception occurred:

Traceback (most recent call last):
  File "/home/sesmart/3_vqa/hqca/tools/Optimizers.py", line 164, in next_step
    self.opt.next_step()
  File "/home/sesmart/3_vqa/hqca/tools/Optimizers.py", line 448, in next_step
    self.R_f = function_call(self.R_x,**self.kwargs)
  File "/home/sesmart/3_vqa/hqca/tools/Optimizers.py", line 68, in function_call
    wait_for_machine(backend)
  File "/home/sesmart/3_vqa/hqca/tools/QuantumFramework.py", line 161, in wait_for_machine
    raise NotAvailableError
NameError: name 'NotAvailableError' is not defined
